Workbook

Sheet Instructions
A1: ASSIGNMENT 1 — 50 Entry-Level Job Postings Analysis (rebuilt template, July 2026)
A3: GOAL: collect 50 GENUINELY ENTRY-LEVEL postings (0-1 years) so course content stays calibrated to what employers actually ask for.
A5: QUALIFYING TITLES: Staff Accountant (entry/junior), AP Clerk/Specialist, AR Clerk/Specialist, Junior Accountant,
A6: Accounting Clerk/Assistant, Bookkeeper, Junior/Entry Financial Analyst.
A7: DISQUALIFIED: anything requiring 2+ years, Senior/Lead/Manager/Supervisor titles, instructors, treasury roles,
A8: government special-agent roles, audit seniors. (These appeared in v1 and skew every statistic.)
A10: HOW TO FILL:
A11: 1. One row per posting on the Postings sheet. Use the dropdowns where provided.
A12: 2. Software and Skills columns: comma-separated, spelled consistently (e.g. 'Excel, QuickBooks, Bill.com').
A13: The Summary sheet counts by substring match, so consistent spelling matters.
A14: 3. CPA / Month-End Close / Reconciliation columns: Yes only if the posting text literally mentions it.
A15: 4. Salary: enter the posted range; leave blank if not disclosed (blanks are excluded from averages).
... A18: TIP: roughly a third of the v1 list (Job_Postings_Raw_List_v1_DRAFT.xlsx) qualifies — migrate those rows first.

Sheet Postings
A1: # | B1: Job Title | C1: Company | D1: Industry | E1: Company Size | F1: Location | G1: Work Mode | H1: Salary Min ($) | I1: Salary Max ($) | J1: Experience Req (yrs) | K1: Education Req | L1: Software (comma-sep) | M1: Skills (comma-sep) | N1: CPA Mentioned | O1: Month-End Close Mentioned | P1: Reconciliation Mentioned | Q1: Source Site | R1: Posting URL | S1: Date Collected
A2: 1 | B2: Entry Level Accountant | C2: Robert Half (client confidential) | F2: Pierceton, IN | G2: Onsite | H2: 60000 | I2: 70000 | J2: 0-1 | K2: Not specified | L2: Excel, accounting software | M2: AP, AR, journal entries, bank reconciliation, account reconciliation, month-end reporting | N2: No | O2: Yes | P2: Yes | Q2: Robert Half | R2: https://www.roberthalf.com/us/en/job/pierceton-in/entry-level-accountant/01420-0013455295-usen
A3: 2 | B3: Accountant - Entry Level | C3: Robert Half (client confidential) | F3: Ramsey/Mahwah, NJ | G3: Onsite | H3: 49400 | I3: 57200 | J3: 0-1 | K3: Not specified | L3: Excel, internal accounting systems | M3: AR, AP, bank reconciliation, account reconciliation, payment posting, data entry, collections | N3: No | O3: No | P3: Yes | Q3: Robert Half | R3: https://www.roberthalf.com/us/en/job/ramsey-nj/accountant-entry-level/02710-0013471284-usen
A4: 3 | B4: Accountant - Entry Level | C4: Robert Half (client confidential) | D4: Luxury hospitality | F4: New York, NY | G4: Onsite | H4: 51376 | I4: 59488 | J4: 0-1 | K4: Not specified | L4: Excel, internal accounting system | M4: Daily cash reconciliation, credit card transaction review, cash balancing, variance follow-up | N4: No | O4: No | P4: Yes | Q4: Robert Half | R4: https://www.roberthalf.com/us/en/job/new-york-ny/accountant-entry-level/02941-0013468203-usen
A5: 4 | B5: Accountant - Entry Level | C5: Robert Half (client confidential) | F5: Salt Lake City, UT | G5: Onsite | H5: 45448 | I5: 52624 | J5: 0-1 | K5: Not specified | L5: Not specified | M5: AP, AR, bank reconciliation, account reconciliation, journal entries, month-end close support | N5: No | O5: Yes | P5: Yes | Q5: Robert Half | R5: https://www.roberthalf.com/us/en/job/salt-lake-city-ut/accountant-entry-level/04210-0013460590-usen
A6: 5 | B6: Contract Entry-Level Accounting Clerk | C6: Robert Half (client confidential) | F6: Stamford, CT | G6: Onsite | H6: 39520 | I6: 47840 | J6: 0-1 | K6: Associate/Bachelor preferred | L6: Excel, MS Office, accounting system | M6: Data entry AP/AR, filing, scanning, statement reconciliation, invoice processing | N6: No | O6: No | P6: Yes | Q6: Robert Half | R6: https://www.roberthalf.com/us/en/job/stamford-ct/accounting-clerk-entry-level/00720-9504355797-usen
A7: 6 | B7: Entry Level Accountant | C7: Robert Half (client confidential) | D7: Transportation | F7: Georgetown, KY | G7: Hybrid | H7: 50000 | I7: 60000 | J7: 1-2 | K7: Bachelor's in Accounting | L7: Excel | M7: Month-end close, journal entries, bank/GL reconciliation, AP, AR, variance analysis | N7: No | O7: Yes | P7: Yes | Q7: Robert Half | R7: https://www.roberthalf.com/us/en/job/georgetown-ky/entry-level-accountant/01710-0013447941-usen
A8: 7 | B8: Accountant - Entry Level | C8: Robert Half (client confidential) | F8: Woodbury, MN | G8: Onsite | H8: 41808 | I8: 48464 | J8: 0-1 | K8: Associate's suggested | L8: Excel, QuickBooks, Great Plains | M8: Data entry, monthly journal entries, discrepancy correction, full-cycle AP/AR | N8: No | O8: No | P8: Yes | Q8: Robert Half | R8: https://www.roberthalf.com/us/en/job/woodbury-mn/accountant-entry-level/02320-9504360477-usen
A9: 8 | B9: Accountant - Entry Level | C9: Robert Half (client confidential) | D9: Retail | F9: Vernon-Rockville, CT | G9: Onsite | H9: 49400 | I9: 57200 | J9: 0-1 | K9: Not specified | L9: Not specified | M9: AP, bank/account reconciliation, journal entries, AR/customer invoicing | N9: No | O9: Yes | P9: Yes | Q9: Robert Half | R9: https://www.roberthalf.com/us/en/job/vernon-rockville-ct/accountant-entry-level/00700-0013466650-usen
A10: 9 | B10: Accountant - Entry Level | C10: Robert Half (client confidential) | D10: Manufacturing | F10: Parsippany, NJ | G10: Onsite | H10: 49400 | I10: 57200 | J10: 0-1 | K10: Not specified | L10: Dynamics NAV, Adobe Acrobat | M10: Account reconciliation, journal entries, month-end tasks, AP, account coding | N10: No | O10: Yes | P10: Yes | Q10: Robert Half | R10: https://www.roberthalf.com/us/en/job/parsippany-nj/accountant-entry-level/02750-0013463404-usen
A11: 10 | B11: Entry Level Accounting Team Member | C11: Robert Half (client confidential) | D11: Energy/Natural Resources | F11: Parsippany, NJ | G11: Onsite | H11: 43472 | I11: 50336 | J11: 0-1 | K11: Not specified | L11: SAP | M11: Vendor invoice processing, payment review, AP operations, invoice reconciliation vs POs | N11: No | O11: No | P11: Yes | Q11: Robert Half | R11: https://www.roberthalf.com/us/en/job/parsippany-nj/entry-level/02750-0013466646-usen
A12: 11 | B12: Entry Level Accountant | C12: Robert Half (client confidential) | D12: Transportation | F12: Georgetown, KY | G12: Onsite | H12: 60000 | I12: 65000 | J12: 1-2 | K12: Bachelor's in Accounting required | L12: Excel | M12: Month-end close, journal entries, bank/GL reconciliation, AP, AR, financial statement prep | N12: No | O12: Yes | P12: Yes | Q12: Robert Half | R12: https://www.roberthalf.com/us/en/job/georgetown-ky/entry-level-accountant/01710-0013461244-usen
A13: 12 | B13: Accountant - Entry Level | C13: Robert Half (client confidential) | F13: New York, NY | G13: Onsite | H13: 47424 | I13: 54912 | J13: 0-1 | K13: Not specified | L13: QuickBooks | M13: Vendor payment processing, AP management, account reconciliation, GL review, admin support | N13: No | O13: No | P13: Yes | Q13: Robert Half | R13: https://www.roberthalf.com/us/en/job/new-york-ny/accountant-entry-level/02941-0013469367-usen
A14: 13 | B14: Financial Analyst - Entry Level | C14: Robert Half (client confidential) | D14: Financial services | F14: Melville, NY | G14: Onsite | H14: 47840 | I14: 52000 | J14: 0 | K14: Bachelor's or Associate's | L14: Excel, MS Office | M14: Financial data review/entry, account maintenance, routine reporting | N14: No | O14: No | P14: No | Q14: Robert Half | R14: https://www.roberthalf.com/us/en/job/melville-ny/financial-analyst-entry-level/02930-0013465888-usen
A15: 14 | B15: Financial Analyst - Entry Level | C15: Robert Half (client confidential) | F15: Menlo Park, CA | G15: Temp-to-hire | H15: 70928 | I15: 82118 | J15: 0-1 | K15: Bachelor's in Finance/Accounting/Econ/Business | L15: Google Sheets, Bloomberg Terminal | M15: Budget tracking, variance analysis, cost monitoring, forecasting, executive reporting | N15: No | O15: No | P15: No | Q15: Robert Half | R15: https://www.roberthalf.com/us/en/job/menlo-park-ca/financial-analyst-entry-level/00370-0013466940-usen
A16: 15 | B16: Financial Analyst - Entry Level | C16: Robert Half (client confidential) | F16: Wyomissing, PA | G16: Onsite | H16: 47840 | I16: 60320 | J16: 0-1 | K16: Bachelor's in Finance/Accounting/Econ/Business | L16: Bloomberg Terminal, spreadsheets, dashboards | M16: Financial data analysis, report prep, market research, dashboard maintenance, variance analysis | N16: No | O16: No | P16: No | Q16: Robert Half | R16: https://www.roberthalf.com/us/en/job/wyomissing-pa/financial-analyst-entry-level/03770-0013469671-usen
A17: 16 | B17: Entry Level Analyst | C17: Robert Half (client confidential) | F17: Dublin, CA | G17: Onsite | H17: 49920 | I17: 58240 | J17: 0-1 | K17: Bachelor's preferred | L17: Excel, MS Office | M17: Data gathering, spreadsheet prep, report creation, trend/inconsistency identification | N17: No | O17: No | P17: No | Q17: Robert Half | R17: https://www.roberthalf.com/us/en/job/dublin-ca/entry-level-analyst/00470-9504355726-usen
A18: 17 | B18: Entry Level Analyst | C18: Robert Half (client confidential) | F18: San Ramon, CA | G18: Temp-to-hire | H18: 49920 | I18: 58240 | J18: 0-1 | K18: Bachelor's preferred | L18: Excel, MS Office | M18: Data analysis, report/dashboard prep, trend ID, data integrity, cross-team support | N18: No | O18: No | P18: No | Q18: Robert Half | R18: https://www.roberthalf.com/us/en/job/san-ramon-ca/entry-level-analyst/00470-9504355724-usen
A19: 18 | B19: Entry Level Analyst | C19: Robert Half (client confidential) | E19: Large (staffing firm) | F19: Bothell, WA | G19: Onsite | H19: 62400 | I19: 83200 | J19: 0-1 | K19: Bachelor's preferred | L19: Workday, Excel | M19: Data entry/reporting, data validation/auditing, trend analysis, large dataset handling | N19: No | O19: No | P19: No | Q19: Robert Half | R19: https://www.roberthalf.com/us/en/job/bothell-wa/entry-level-analyst/03640-9504357825-usen
A20: 19 | B20: Accounts Payable Clerk | C20: Robert Half (client confidential) | F20: Dallas, TX | G20: Onsite | H20: 55328 | I20: 64064 | J20: 0-1 | K20: Not specified | L20: PeopleSoft | M20: Invoice review, GL coding, payment processing, 1099 prep, vendor workflow | N20: No | O20: No | P20: No | Q20: Robert Half | R20: https://www.roberthalf.com/us/en/job/dallas-tx/accounts-payable-clerk/04120-0013463310-usen
A21: 20 | B21: Accounts Payable Clerk | C21: Robert Half (client confidential) | F21: Columbus, OH | G21: Onsite | H21: 43680 | I21: 49920 | J21: 0-1 | K21: Not specified | L21: Dynamics 365 F&O (D365) | M21: Invoice review, accounting code assignment, discrepancy investigation, email/documentation | N21: No | O21: No | P21: No | Q21: Robert Half | R21: https://www.roberthalf.com/us/en/job/columbus-oh/accounts-payable-clerk/03360-0013468339-usen
A22: 21 | B22: Accounts Payable Clerk | C22: Robert Half (client confidential) | F22: Naples, FL | G22: Onsite | H22: 44460 | I22: 51480 | J22: 0-1 | K22: Not specified | L22: Accounting software, Excel | M22: Invoice review/coding, payment processing, check runs, payable reconciliation, vendor comms | N22: No | O22: No | P22: Yes | Q22: Robert Half | R22: https://www.roberthalf.com/us/en/job/naples-fl/accounts-payable-clerk/01150-0013460026-usen
A23: 22 | B23: Accounts Payable Clerk | C23: Robert Half (client confidential) | D23: Import/Export | F23: Covington, LA | G23: Onsite | H23: 33280 | I23: 37440 | J23: 0-1 | K23: Not specified | L23: Excel | M23: Invoice review/coding, check runs, vendor payment management, reconciliation | N23: No | O23: No | P23: Yes | Q23: Robert Half | R23: https://www.roberthalf.com/us/en/job/covington-la/accounts-payable-clerk/04640-0013454929-usen
A24: 23 | B24: Accounts Payable Clerk | C24: Robert Half (client confidential) | D24: Manufacturing | F24: Carson City, NV | G24: Onsite | H24: 45760 | I24: 54080 | J24: 0-1 | K24: Not specified | L24: Accounting system (unspecified) | M24: AP transaction/journal entry, invoice processing, check runs, high-volume data entry | N24: No | O24: No | P24: No | Q24: Robert Half | R24: https://www.roberthalf.com/us/en/job/carson-city-nv/accounts-payable-clerk/03110-0013445268-usen
A25: 24 | B25: Accounts Payable Clerk | C25: Robert Half (client confidential) | D25: Wholesale distribution | F25: Cleveland, OH | G25: Onsite | H25: 43472 | I25: 50336 | J25: 0-1 | K25: Not specified | L25: SAP | M25: Invoice/GL coding review, exception investigation, transaction monitoring | N25: No | O25: No | P25: No | Q25: Robert Half | R25: https://www.roberthalf.com/us/en/job/cleveland-oh/accounts-payable-clerk/03340-0013459238-usen
A26: 25 | B26: Bookkeeper | C26: Robert Half (client confidential) | F26: Orlando, FL | G26: Contract-to-perm | H26: 37440 | I26: 43680 | J26: 1 | K26: Not specified | L26: QuickBooks, MS Office | M26: AP/AR management, bank reconciliation, payroll processing, invoice entry | N26: No | O26: No | P26: Yes | Q26: Robert Half | R26: https://www.roberthalf.com/us/en/job/orlando-fl/bookkeeper/01030-0013468226-usen
A27: 26 | B27: Bookkeeper | C27: Robert Half (client confidential) | F27: Keene, NH | G27: Onsite | H27: 49920 | I27: 54080 | J27: 0-1 | K27: Not specified | L27: QuickBooks/cloud systems, spreadsheets | M27: Bank/account reconciliation, AP/AR, GL support, month-end activities | N27: No | O27: Yes | P27: Yes | Q27: Robert Half | R27: https://www.roberthalf.com/us/en/job/keene-nh/bookkeeper/02600-0013455233-usen
A28: 27 | B28: Bookkeeper | C28: Robert Half (client confidential) | E28: Small team | F28: Coraopolis, PA | G28: Onsite (1 day/wk) | H28: 41600 | I28: 52000 | J28: 0-1 | K28: Not specified | L28: QuickBooks | M28: Monthly bank reconciliation, biweekly payroll, P&L/balance sheet prep | N28: No | O28: Yes | P28: Yes | Q28: Robert Half | R28: https://www.roberthalf.com/us/en/job/coraopolis-pa/bookkeeper/03810-0013466070-usen
A29: 28 | B29: Accounts Receivable Clerk | C29: Robert Half (client confidential) | F29: Perry, GA | G29: Onsite | H29: 41600 | I29: 43680 | J29: 0-1 | K29: Not specified | L29: Not specified | M29: Invoice processing, payment application, collections outreach, account reconciliation | N29: No | O29: No | P29: Yes | Q29: Robert Half | R29: https://www.roberthalf.com/us/en/job/perry-ga/accounts-receivable-clerk/00930-0013436781-usen
A30: 29 | B30: Accounts Receivable Clerk | C30: Robert Half (client confidential) | E30: Large (staffing firm) | F30: Buffalo, NY | G30: Onsite | H30: 47840 | I30: 54080 | J30: 1 | K30: HS diploma; Associate's preferred | L30: Excel, ERP (SAP/Oracle/NetSuite/Sage/Dynamics) | M30: Payment processing, invoicing, collections, reconciliation, aging reports, month-end close | N30: No | O30: Yes | P30: Yes | Q30: Robert Half | R30: https://www.roberthalf.com/us/en/job/buffalo-ny/accounts-receivable-clerk/02920-9504361528-usen
A31: 30 | B31: Accounts Receivable Clerk | C31: Robert Half (client confidential) | D31: Environmental/Waste management | F31: Odessa, TX | G31: Onsite | H31: 39520 | I31: 45760 | J31: 0-1 | K31: Not specified | L31: NetSuite, Open Invoice, Open Ticket | M31: AR cycle management, invoice creation, payment application, account balancing | N31: No | O31: No | P31: Yes | Q31: Robert Half | R31: https://www.roberthalf.com/us/en/job/odessa-tx/accounts-receivable-clerk/04190-0013471449-usen
A32: 31 | B32: Accounts Receivable Clerk | C32: Robert Half (client confidential) | F32: Newport News, VA | G32: Onsite | H32: 37544 | I32: 43472 | J32: 0-1 | K32: Not specified | L32: Excel | M32: Customer payment posting/reconciliation, invoice retrieval, report generation, delinquent review | N32: No | O32: No | P32: Yes | Q32: Robert Half | R32: https://www.roberthalf.com/us/en/job/newport-news-va/accounts-receivable-clerk/04550-0013466137-usen
A33: 32 | B33: Accounts Receivable Clerk | C33: Robert Half (client confidential) | D33: Construction | F33: San Marcos, CA | G33: Onsite | H33: 52000 | I33: 56160 | J33: 1-3 | K33: Not specified | L33: QuickBooks, Sage, Vista/Viewpoint, Excel | M33: Invoice prep, payment posting, account reconciliation, collections, month-end reporting | N33: No | O33: Yes | P33: Yes | Q33: Robert Half | R33: https://www.roberthalf.com/us/en/job/san-marcos-ca/accounts-receivable-clerk/00240-9504356470-usen
A34: 33 | B34: Accounts Receivable Clerk | C34: Robert Half (client confidential) | E34: Large (staffing firm) | F34: Pasadena, CA | G34: Temp/Contract | H34: 41600 | I34: 45760 | J34: 1 | K34: Not specified | L34: Excel | M34: Invoice generation, billing dispute resolution, cash application, aging report analysis | N34: No | O34: No | P34: Yes | Q34: Robert Half | R34: https://www.roberthalf.com/us/en/job/pasadena-ca/accounts-receivable-clerk/00490-9504298267-usen
A35: 34 | B35: Bookkeeper | C35: Robert Half (client confidential) | F35: Trenton, NJ | G35: Onsite | H35: 52000 | I35: 62400 | J35: 0-1 | K35: Not specified | L35: Excel, accounting software (unspecified) | M35: Journal entries, GL maintenance, bank/credit card reconciliation, AP/AR, month-end close | N35: No | O35: Yes | P35: Yes | Q35: Robert Half | R35: https://www.roberthalf.com/us/en/job/trenton-nj/bookkeeper/02760-0013468704-usen
A36: 35 | B36: Bookkeeper | C36: Robert Half (client confidential) | D36: Multi-location retail-type ops | F36: Little Rock, AR | G36: Onsite | H36: 45448 | I36: 52624 | J36: 0-1 | K36: Not specified | L36: Standard accounting/spreadsheet tools | M36: Cash management, deposit oversight, cash posting, bank deposits and reconciliation | N36: No | O36: No | P36: Yes | Q36: Robert Half | R36: https://www.roberthalf.com/us/en/job/little-rock-ar/bookkeeper/03000-0013469121-usen
A37: 36 | B37: Accounts Payable Clerk | C37: Robert Half (client confidential) | F37: Greensboro/Winston-Salem, NC | G37: Onsite | H37: 45760 | I37: 49920 | J37: 0-1 | K37: Not specified | L37: Accounting systems, standard office software | M37: Invoice processing, accounting code assignment, check runs, PO/receipt reconciliation | N37: No | O37: No | P37: Yes | Q37: Robert Half | R37: https://www.roberthalf.com/us/en/job/greensboro-nc/accounts-payable-clerk/03210-0013463654-usen
A38: 37 | B38: Accounts Receivable Clerk | C38: Robert Half (client confidential) | F38: Indianapolis, IN | G38: Onsite | H38: 45760 | I38: 56160 | J38: 0-1 | K38: Not specified | L38: Salesforce | M38: Invoice creation, contract record maintenance, balance monitoring, collections/dunning | N38: No | O38: No | P38: No | Q38: Robert Half | R38: https://www.roberthalf.com/us/en/job/indianapolis-in/accounts-receivable-clerk/01400-0013468304-usen
A39: 38 | B39: Accounts Payable Clerk | C39: Robert Half (client confidential) | F39: Irvine/Lake Forest, CA | G39: Onsite | H39: 49400 | I39: 56160 | J39: 0-1 | K39: Not specified | L39: Accounting software (unspecified) | M39: Invoice review/coding, transaction entry, check runs, PO/receipt reconciliation | N39: No | O39: No | P39: Yes | Q39: Robert Half | R39: https://www.roberthalf.com/us/en/job/irvine-ca/accounts-payable-clerk/00760-0013469577-usen
A40: 39 | B40: Accounts Payable Clerk | C40: Robert Half (client confidential) | D40: Construction | F40: San Ramon, CA | G40: Onsite | H40: 47840 | I40: 65520 | J40: 0-1 | K40: Not specified | L40: Metaviewer, Oracle JD Edwards EnterpriseOne | M40: High-volume AP processing, invoice coding, check requests, vendor statement reconciliation | N40: No | O40: Yes | P40: Yes | Q40: Robert Half | R40: https://www.roberthalf.com/us/en/job/san-ramon-ca/accounts-payable-clerk/04692-0013469958-usen
...

Sheet Summary
A1: Job Postings Analysis — Summary (auto-calculated once Postings sheet is filled)
A3: Postings collected | B3: =COUNTA(Postings!B2:B51)
A4: Average salary min | B4: =IFERROR(ROUND(AVERAGE(Postings!H2:H51),0),"—")
A5: Average salary max | B5: =IFERROR(ROUND(AVERAGE(Postings!I2:I51),0),"—")
A6: % requiring 0 or 0-1 yrs experience | B6: =IFERROR(TEXT((COUNTIF(Postings!J2:J51,"0")+COUNTIF(Postings!J2:J51,"0-1"))/COUNTA(Postings!J2:J51),"0%"),"—")
A7: % mentioning CPA | B7: =IFERROR(TEXT(COUNTIF(Postings!N2:N51,"Yes")/COUNTA(Postings!N2:N51),"0%"),"—")
A8: % mentioning month-end close | B8: =IFERROR(TEXT(COUNTIF(Postings!O2:O51,"Yes")/COUNTA(Postings!O2:O51),"0%"),"—")
A9: % mentioning reconciliation | B9: =IFERROR(TEXT(COUNTIF(Postings!P2:P51,"Yes")/COUNTA(Postings!P2:P51),"0%"),"—")
A11: Top job titles (count)
A12: Staff Accountant | B12: =COUNTIF(Postings!B2:B51,"*"&A12&"*")
A13: Accounts Payable Clerk | B13: =COUNTIF(Postings!B2:B51,"*"&A13&"*")
A14: Accounts Receivable Clerk | B14: =COUNTIF(Postings!B2:B51,"*"&A14&"*")
A15: Junior Accountant | B15: =COUNTIF(Postings!B2:B51,"*"&A15&"*")
A16: Financial Analyst | B16: =COUNTIF(Postings!B2:B51,"*"&A16&"*")
A17: Bookkeeper | B17: =COUNTIF(Postings!B2:B51,"*"&A17&"*")
A18: Accounting Clerk | B18: =COUNTIF(Postings!B2:B51,"*"&A18&"*")
A19: Accounting Assistant | B19: =COUNTIF(Postings!B2:B51,"*"&A19&"*")
A21: Software frequency (count of postings naming it)
A22: Excel | B22: =COUNTIF(Postings!L2:L51,"*"&A22&"*")
A23: QuickBooks | B23: =COUNTIF(Postings!L2:L51,"*"&A23&"*")
A24: NetSuite | B24: =COUNTIF(Postings!L2:L51,"*"&A24&"*")
A25: SAP | B25: =COUNTIF(Postings!L2:L51,"*"&A25&"*")
A26: Oracle | B26: =COUNTIF(Postings!L2:L51,"*"&A26&"*")
A27: Sage | B27: =COUNTIF(Postings!L2:L51,"*"&A27&"*")
A28: Bill.com | B28: =COUNTIF(Postings!L2:L51,"*"&A28&"*")
A29: Concur | B29: =COUNTIF(Postings!L2:L51,"*"&A29&"*")
A30: ADP | B30: =COUNTIF(Postings!L2:L51,"*"&A30&"*")
A31: Workday | B31: =COUNTIF(Postings!L2:L51,"*"&A31&"*")
A32: Microsoft Dynamics | B32: =COUNTIF(Postings!L2:L51,"*"&A32&"*")
A33: Xero | B33: =COUNTIF(Postings!L2:L51,"*"&A33&"*")
A36: Skill frequency (count of postings naming it)
A37: Month-end close | B37: =COUNTIF(Postings!M2:M51,"*"&A37&"*")+COUNTIF(Postings!L2:L51,"*"&A37&"*")
A38: Bank reconciliation | B38: =COUNTIF(Postings!M2:M51,"*"&A38&"*")+COUNTIF(Postings!L2:L51,"*"&A38&"*")
A39: Journal entries | B39: =COUNTIF(Postings!M2:M51,"*"&A39&"*")+COUNTIF(Postings!L2:L51,"*"&A39&"*")
A40: General ledger | B40: =COUNTIF(Postings!M2:M51,"*"&A40&"*")+COUNTIF(Postings!L2:L51,"*"&A40&"*")
A41: Accounts payable | B41: =COUNTIF(Postings!M2:M51,"*"&A41&"*")+COUNTIF(Postings!L2:L51,"*"&A41&"*")
A42: Accounts receivable | B42: =COUNTIF(Postings!M2:M51,"*"&A42&"*")+COUNTIF(Postings!L2:L51,"*"&A42&"*")
A43: Pivot tables | B43: =COUNTIF(Postings!M2:M51,"*"&A43&"*")+COUNTIF(Postings!L2:L51,"*"&A43&"*")
A44: VLOOKUP | B44: =COUNTIF(Postings!M2:M51,"*"&A44&"*")+COUNTIF(Postings!L2:L51,"*"&A44&"*")
A45: XLOOKUP | B45: =COUNTIF(Postings!M2:M51,"*"&A45&"*")+COUNTIF(Postings!L2:L51,"*"&A45&"*")
...
